<?xml version="1.0"?>
<robot name="simple_serial_robot">

  <material name="blue">
    <color rgba="0 0 0.8 1"/>
  </material>
  <material name="black">
    <color rgba="0 0 0 1"/>
  </material>
  <material name="white">
    <color rgba="1 1 1 1"/>
  </material>

  <link name="base_link">
    <visual>
      <geometry>
        <box size="0.3 0.3 0.1"/>
      </geometry>
      <material name="blue"/>
    </visual>
  </link>

  <link name="staple">
    <visual>
      <geometry>
        <box size="0.01 0.2 0.2"/>
      </geometry>
      <material name="blue"/>
    </visual>
  </link>

  <joint name="staple_to_base_link" type="fixed">
    <parent link="base_link"/>
    <child link="staple"/>
    <origin xyz="-0.055 0 0.1"/>
  </joint>

  <link name="link1">
    <visual>
      <geometry>
        <box size="0.1 0.1 0.4"/>
      </geometry>
      <origin xyz="0 0 0.16"/>
      <material name="white"/>
    </visual>
  </link>

  <joint name="link1_to_staple" type="revolute">
    <parent link="staple"/>
    <child link="link1"/>
    <origin xyz="0.055 0 0.05"/>
    <limit lower="-1.57" upper="1.57" effort="1000.0" velocity="0.5"/>
  </joint>

<!-- ADD NEW LINKS AND JOINTS HERE -->



</robot>
